Workbook

Sheet 안내
A1: E2E 시나리오 통합본 안내
A3: [이 문서의 위치]
A4: 미션 3의 3단계 산출물이다. 팀원 3명의 초안(초안 A·B·C)을 취합하고 중복을 제거했다. 다음 단계(4단계)에서 시나리오별 담당자를 정한다.
A6: [취합 기준]
A7: 초안 A: 영역별로 가장 세분화된 초안(65개, 로케이터·DB 변경 포함). 초안 B: 영역별 초안(34개, 기존 자동테스트 여부 포함). 초안 C: 사용자 흐름 단위의 긴 시나리오 10개.
A8: 1. 가장 세분화된 초안 A를 바탕으로 했고 ID 는 그대로 유지했다. 이미 코드가 ID 를 쓰고 있다(login.spec.ts 의 AUTH-01, AUTH-02).
A9: 2. 초안 B(34개)와 초안 C(10개)에서 같은 동작을 검증하는 시나리오는 하나로 합쳤다. 어떤 시나리오가 어디로 합쳐졌는지는 '출처 매핑' 시트에 있다.
A10: 3. 초안에 없던 내용 중 PRD 에서 검증해야 하는 것은 신규로 추가했다(초록색 ID 칸, 출처에 '신규' 또는 초안 이름 표시).
A11: 4. 우선순위는 초안 A의 P1/P2/P3 로 통일했다. 초안 B의 상/중/하 와 다른 항목은 '출처 매핑' 시트의 비고에 적었다.
A13: [열 설명]
A14: 우선순위: P1(핵심 흐름과 데이터 정합성, 배포 전 반드시 통과) / P2(주요 기능의 변형·경계·예외) / P3(보조 기능, UI 세부, 환경 의존)
A15: 유형: 정상(기대 흐름) / 예외(잘못된 입력·권한·충돌) / 경계(허용 한계값)
... A37: - 목록 건수는 절대값이 아니라 전후 차이로 검증한다.

Sheet 시나리오
A1: Playwright E2E 테스트 시나리오 (통합본)
A4: ID | B4: 영역 | C4: 시나리오 | D4: 유형 | E4: 우선순위 | F4: 사전조건 | G4: 테스트 단계 | H4: 기대 결과 | I4: 관련 PRD 항목 | J4: 주요 로케이터 / 대상 | K4: DB 변경 | L4: 기존 자동테스트 | M4: 담당자 | N4: 구현 상태 | O4: 메모
A5: AUTH-01 | B5: 인증 | C5: 비로그인 상태에서 보호된 화면 접근 시 로그인 화면으로 이동 | D5: 예외 | E5: P1 | F5: 로그아웃 상태(새 브라우저 컨텍스트) | G5: 1. /orders 로 이동 | H5: /login 으로 리다이렉트된다 | I5: FR-20 | J5: page.goto('/orders') → toHaveURL(/\/login$/) | K5: N | L5: 있음(OrderFlowTests, API 수준) | N5: 미작성
A6: AUTH-02 | B6: 인증 | C6: admin/admin 로그인 성공 | D6: 정상 | E6: P1 | F6: 로그아웃 상태 | G6: 1. /login 이동 2. 아이디 admin, 비밀번호 admin 입력 3. 로그인 클릭 | H6: /orders 로 이동하고 주문 목록 화면이 보인다 | I6: FR-20, FR-21 | J6: input[name=username], input[name=password], button[type=submit] | K6: N | L6: 없음 | N6: 미작성
A7: AUTH-03 | B7: 인증 | C7: 잘못된 비밀번호로 로그인 실패 | D7: 예외 | E7: P1 | F7: 로그아웃 상태 | G7: 1. /login 이동 2. admin / wrong 입력 후 로그인 | H7: 로그인 화면에 머물고 '아이디 또는 비밀번호가 올바르지 않습니다' 가 표시된다. 세션이 생기지 않아 /orders 접근 시 다시 로그인으로 간다 | I7: FR-20 | J7: .alert.error | K7: N | L7: 있음(OrderFlowTests, API 수준) | N7: 미작성
A8: AUTH-04 | B8: 인증 | C8: 로그인 상태에서 /login 접근 시 목록으로 이동 | D8: 정상 | E8: P3 | F8: 로그인 상태 | G8: 1. /login 이동 | H8: /orders 로 리다이렉트된다 | I8: FR-20 | J8: page.goto('/login') | K8: N | L8: 없음 | N8: 미작성
A9: AUTH-05 | B9: 인증 | C9: 로그아웃 | D9: 정상 | E9: P1 | F9: 로그인 상태 | G9: 1. 상단 '로그아웃' 클릭 2. /orders 로 직접 이동 | H9: /login 으로 이동하고, 이후 /orders 접근이 다시 로그인 화면으로 차단된다 | I9: FR-20 | J9: header .user button.link | K9: N | L9: 없음 | N9: 미작성
A10: AUTH-06 | B10: 인증 | C10: 상단에 로그인 사용자 표시 | D10: 정상 | E10: P3 | F10: 로그인 상태 | G10: 1. 아무 화면 열기 | H10: 상단 우측에 'admin' 과 로그아웃 버튼이 보인다 | I10: FR-21 | J10: header .user span | K10: N | L10: 미확인 | N10: 미작성
A11: AUTH-07 | B11: 인증 | C11: 비로그인 API 호출은 401 | D11: 예외 | E11: P2 | F11: 로그아웃 상태 | G11: 1. request.get('/api/master') 2. request.post('/api/simulate', {orders: {...}}) | H11: 두 요청 모두 HTTP 401 (리다이렉트가 아님) | I11: FR-20 | J11: playwright request 컨텍스트(쿠키 없음) | K11: N | L11: 없음 | N11: 미작성
A12: AUTH-08 | B12: 인증 | C12: 정적 리소스는 로그인 없이 접근 가능 | D12: 정상 | E12: P3 | F12: 로그아웃 상태 | G12: 1. /css/app.css, /js/common.js 요청 | H12: HTTP 200 (인터셉터 제외 경로) | I12: FR-20 | J12: request.get | K12: N | L12: 미확인 | N12: 미작성
A13: AUTH-09 | B13: 인증 | C13: 비로그인 상태에서 상태 변경 요청은 로그인으로 이동하고 변경되지 않음 | D13: 예외 | E13: P2 | F13: 로그아웃 상태, 확정 상태 주문이 있음 | G13: 1. request.post('/orders/{id}/status', form: status=IN_PROGRESS, version=현재값, maxRedirects: 0) | H13: HTTP 302 로 /login 으로 이동한다. 로그인 후 주문 상태를 확인하면 '확정' 그대로이고 이력도 늘지 않는다 | I13: FR-20 | J13: playwright request 컨텍스트(쿠키 없음) | K13: N | L13: 미확인 | N13: 미작성 | O13: 인터셉터가 /api/ 가 아닌 경로는 401 이 아니라 /login 리다이렉트로 처리함(코드 확인)
A14: SIM-01 | B14: 주문 추가·시뮬레이션 | C14: 주문 추가 화면 초기 상태 | D14: 정상 | E14: P1 | F14: 로그인 상태 | G14: 1. /orders/new 이동 | H14: 총 생산 필요 수 12000, 게이지 4개(중국·일본·베트남·인도네시아) 각 3000K. 방문 횟수: 중국 1회, 일본 2회, 베트남 1회, 인도네시아 1회. 결과 영역은 숨김 | I14: FR-1, FR-19 | J14: #total, .gauge[data-c] .gnum, .gvisits, #result[hidden] | K14: N | L14: 없음 | N14: 미작성 | O14: 방문 횟수 기대값은 '테스트 데이터' 시트 참고
A15: SIM-02 | B15: 주문 추가·시뮬레이션 | C15: 시뮬레이션 실행 시 경로 3종 표시 | D15: 정상 | E15: P1 | F15: SIM-01 상태 | G15: 1. '시뮬레이션 실행' 클릭 | H15: 결과 영역이 보이고 옵션 카드 3개(운항비 최소 / 가장 빠르게 / 가까운 곳부터)에 소요 일수와 총 비용(억원)이 표시된다. 기본 선택은 운항비 최소 | I15: FR-2, FR-3 | J15: #runBtn, #options .option[data-type=COST|FAST|NEAR] | K15: N | L15: 있음(OrderFlowTests, API 수준) | N15: 미작성
A16: SIM-03 | B16: 주문 추가·시뮬레이션 | C16: 옵션 카드 클릭 시 선택·요약 갱신 | D16: 정상 | E16: P2 | F16: SIM-02 완료 상태 | G16: 1. '가장 빠르게' 카드 클릭 | H16: 해당 카드만 selected 가 되고 요약·상세 표·지도 애니메이션이 그 경로 기준으로 바뀐다 | I16: FR-3 | J16: #options .option.selected, #summary | K16: N | L16: 없음 | N16: 미작성
A17: SIM-04 | B17: 주문 추가·시뮬레이션 | C17: FAST 소요 일수 ≤ COST 소요 일수, COST 총비용 ≤ FAST 총비용 | D17: 정상 | E17: P2 | F17: SIM-02 완료 상태 | G17: 1. 세 카드의 소요 일수·총 비용 텍스트를 읽어 숫자로 변환 2. 대소 비교 | H17: 가장 빠르게 안이 더 느리지 않고, 운항비 최소 안의 총 비용이 더 비싸지 않다 | I17: FR-2, 수용 기준 | J17: #options .option 텍스트 | K17: N | L17: 미확인 | N17: 미작성 | O17: 화면 값 파싱 필요(‘소요 N일’, ‘총 비용 N.NN억원’)
A18: SIM-05 | B18: 주문 추가·시뮬레이션 | C18: 총 수량 변경 시 균등 분배 + 이전 결과 무효화 | D18: 정상 | E18: P1 | F18: SIM-02 완료 상태 | G18: 1. #total 을 10000 으로 변경(change 이벤트) | H18: 게이지가 2500K씩으로 재분배되고 결과 영역이 숨겨진다(확정 불가) | I18: FR-1 | J18: #total, #result[hidden] | K18: N | L18: 없음 | N18: 미작성
A19: SIM-06 | B19: 주문 추가·시뮬레이션 | C19: 게이지 조정 시 오른쪽 이웃이 반대로 조정되고 합계 유지 | D19: 정상 | E19: P1 | F19: SIM-01 상태(각 3000) | G19: 1. 중국 숫자칸을 5000 으로 변경 | H19: 중국 5000, 일본 1000, 나머지 3000. 합계 12000 유지. 방문 횟수 라벨 갱신(중국 2회, 일본 1회) | I19: FR-1 | J19: .gauge[data-c=CHINA] .gnum, .gauge[data-c=JAPAN] .gnum | K19: N | L19: 없음 | N19: 미작성
A20: SIM-07 | B20: 주문 추가·시뮬레이션 | C20: 맨 오른쪽(인도네시아) 조정 시 맨 왼쪽(중국)이 조정됨 | D20: 정상 | E20: P2 | F20: SIM-01 상태 | G20: 1. 인도네시아 숫자칸을 4000 으로 변경 | H20: 인도네시아 4000, 중국 2000, 합계 12000 | I20: FR-1 | J20: .gauge[data-c=INDONESIA] .gnum | K20: N | L20: 미확인 | N20: 미작성
A21: SIM-08 | B21: 주문 추가·시뮬레이션 | C21: 이웃 합계를 넘는 값은 상한으로 보정 | D21: 경계 | E21: P2 | F21: SIM-01 상태(중국+일본=6000) | G21: 1. 중국 숫자칸을 9999 로 변경 | H21: 중국 6000, 일본 0 으로 보정된다(합계 유지) | I21: FR-1 | J21: .gnum | K21: N | L21: 없음 | N21: 미작성
A22: SIM-09 | B22: 주문 추가·시뮬레이션 | C22: 수량 변경 시 이전 시뮬레이션 결과 숨김 | D22: 정상 | E22: P2 | F22: SIM-02 완료 상태 | G22: 1. 일본 숫자칸 변경 | H22: 결과 영역이 숨겨지고 '주문 확정' 을 누를 수 없는 상태가 된다 | I22: INTENT 의도 3 | J22: #result[hidden] | K22: N | L22: 없음 | N22: 미작성
A23: SIM-10 | B23: 주문 추가·시뮬레이션 | C23: 총 수량 0 입력은 이전 값으로 복원 | D23: 경계 | E23: P3 | F23: SIM-01 상태 | G23: 1. #total 에 0 입력 후 change | H23: 입력칸이 12000 으로 되돌아가고 게이지는 그대로 | I23: FR-6 | J23: #total | K23: N | L23: 없음 | N23: 미작성
A24: SIM-11 | B24: 주문 추가·시뮬레이션 | C24: 최소 수량 1K 시뮬레이션 | D24: 경계 | E24: P2 | F24: SIM-01 상태 | G24: 1. #total 에 1 입력 2. 시뮬레이션 실행 | H24: 오류 없이 결과 표시. 수량이 있는 한 나라만 방문하는 경로가 나온다 | I24: FR-6 | J24: #total=1 | K24: N | L24: 미확인 | N24: 미작성
A25: SIM-12 | B25: 주문 추가·시뮬레이션 | C25: 최대 수량 100,000K 시뮬레이션 | D25: 경계 | E25: P2 | F25: SIM-01 상태 | G25: 1. #total 에 100000 입력 2. 시뮬레이션 실행(타임아웃 길게) | H25: 오류 없이 결과 표시. 방문 횟수가 많아도 응답이 제한 시간 내에 온다 | I25: FR-6 | J25: #total=100000 | K25: N | L25: 미확인 | N25: 미작성 | O25: 계산량이 큰 입력. 응답 시간 측정/타임아웃 설정 필요
A26: SIM-13 | B26: 주문 추가·시뮬레이션 | C26: 최대 수량 초과(100,001K) 서버 검증 | D26: 예외 | E26: P1 | F26: SIM-01 상태 | G26: 1. #total 에 100001 입력 2. 시뮬레이션 실행 | H26: #inputError 에 '총 생산 필요 수는 100,000K 이하여야 합니다' 표시, 결과 영역은 숨김 유지 | I26: FR-6 | J26: #inputError | K26: N | L26: 없음 | N26: 미작성 | O26: 입력칸은 max 속성이 있어도 change 핸들러는 허용 → 서버 오류 경로 검증
A27: SIM-14 | B27: 주문 추가·시뮬레이션 | C27: 재고 상한을 넘는 주문의 방문 횟수(올림 계산) | D27: 경계 | E27: P2 | F27: SIM-01 상태(중국+일본=6000) | G27: 1. 중국 숫자칸을 6000 으로 변경(일본 0) 2. 시뮬레이션 실행 | H27: 중국 '방문 2회'(6000÷4000 올림), 일본 '방문 0회'. 시뮬레이션이 성공하고 중국을 두 번 나눠 수거하는 일정이 나온다 | I27: FR-4 | J27: .gvisits, #details | K27: N | L27: 미확인 | N27: 미작성
A28: SIM-15 | B28: 주문 추가·시뮬레이션 | C28: 상세 표 렌더링(주문·배 일정·일별 재고/생산·마스터) | D28: 정상 | E28: P2 | F28: SIM-02 완료 상태 | G28: 1. #details 영역 확인 | H28: 주문 수량 표, 배별 왕복 일정 표, 일별 표, 마스터 스냅샷 표가 비어 있지 않다 | I28: FR-3 | J28: #details table | K28: N | L28: 미확인 | N28: 미작성
A29: SIM-16 | B29: 주문 추가·시뮬레이션 | C29: 지도 애니메이션 렌더·재생 | D29: 정상 | E29: P3 | F29: SIM-02 완료 상태 | G29: 1. #anim 영역 확인 2. 재생/일시정지(있는 컨트롤) 조작 | H29: 지도 이미지와 배 아이콘이 표시되고 시간이 흐르면 위치가 바뀐다 | I29: - | J29: #anim | K29: N | L29: 없음 | N29: 미작성 | O29: 시간 의존 → 스냅샷 비교 지양, 요소 존재·값 변화만 확인
A30: SIM-17 | B30: 주문 추가·시뮬레이션 | C30: 시뮬레이션 중 버튼 중복 클릭 방지 | D30: 정상 | E30: P3 | F30: SIM-01 상태 | G30: 1. '시뮬레이션 실행' 연속 클릭 | H30: 요청 중에는 버튼이 disabled, 완료 후 다시 활성화된다 | I30: - | J30: #runBtn | K30: N | L30: 미확인 | N30: 미작성
A31: SIM-18 | B31: 주문 추가·시뮬레이션 | C31: 재고 상한을 넘는 일본 4,500K 단독 주문은 3번에 나눠 수거 | D31: 경계 | E31: P1 | F31: SIM-01 상태(기본 마스터, 일본 재고 상한 2,000K) | G31: 1. #total 을 4500 으로 변경 / 2. 게이지 연동 규칙으로 일본 4,500K, 나머지 0K 로 맞춘다 (예: 베트남 → 인도네시아 → 중국 순서로 각각 0 입력) / 3. 일본 방문 횟수 확인 / 4. 시뮬레이션 실행 후 세 경로의 '배 경로' 표 확인 | H31: 일본 '방문 3회'. 세 경로 모두 일본 왕복이 3번이고 일본 적재량이 순서대로 2,000K·2,000K·500K(합 4,500K). 한국에 돌아온 뒤 다시 출항하는 왕복 3줄이 표에 나온다 | I31: FR-4 | J31: .gauge[data-c=JAPAN] .gvisits, #details | K31: N | L31: 미확인 | N31: 미작성
A32: SIM-19 | B32: 주문 추가·시뮬레이션 | C32: 세 경로 모두 나라별 적재량 합이 주문 수량과 같음 | D32: 정상 | E32: P2 | F32: SIM-02 완료 상태(기본 주문 3,000K × 4) | G32: 1. 세 경로 카드를 차례로 선택 / 2. 각 경로의 '배 경로' 표에서 나라별 적재량을 모두 더한다 | H32: 모든 경로에서 중국·베트남·인도네시아는 3,000K, 일본은 2,000K + 1,000K = 3,000K 이다 | I32: FR-4 | J32: #details 의 배 경로 표 | K32: N | L32: 미확인 | N32: 미작성 | O32: PRD FR-4(한 번에 다 싣는 규칙)와 수용 기준. 표 열 이름은 실행 후 확인
A33: SIM-20 | B33: 주문 추가·시뮬레이션 | C33: 기본 주문(12,000K 균등)의 생산 원가는 어느 경로든 78.00억원 | D33: 정상 | E33: P2 | F33: SIM-02 완료 상태 | G33: 1. 세 경로 카드를 차례로 선택 / 2. 요약의 '생산 원가' 확인 | H33: 세 경로 모두 생산 원가가 78.00억원이다 (생산 원가는 수량 × 셀당 원가라 경로와 무관) | I33: FR-5 | J33: #summary 의 생산 원가 | K33: N | L33: 미확인 | N33: 미작성 | O33: '테스트 데이터' 시트 계산과 같음. 마스터 기본값이 바뀌면 기대값도 바뀜
A34: SIM-21 | B34: 주문 추가·시뮬레이션 | C34: 베트남 2,000K 단독 주문: 늦게 출항하고 한국 대기는 운항비가 들지 않음 | D34: 경계 | E34: P2 | F34: SIM-01 상태(기본 마스터: 베트남 하루 200K, 한국–베트남 5일, 배 3척) | G34: 1. #total 을 2000 으로 변경(각 500K) / 2. 게이지를 베트남 2,000K, 나머지 0K 로 맞춘다 (예: 중국 → 일본 → 인도네시아 → 중국 → 일본 순서로 각각 0 입력) / 3. 시뮬레이션 실행 | H34: 세 경로 모두 배 1척, 5일째 출항 · 10일째 도착 · 15일째 한국 복귀. 소요 15일, 운항비 10.00억원(바다에서 10일), 생산 원가 11.00억원, 총 비용 21.00억원 | I34: FR-4, FR-5 | J34: #options, #summary, #details | K34: N | L34: 미확인 | N34: 미작성 | O34: 손으로 계산해 확인한 값(생산 10일 − 항해 5일 = 5일째 출항). 표 열 이름은 실행 후 확인
A35: SIM-22 | B35: 주문 추가·시뮬레이션 | C35: 한 나라는 한 척의 배만 방문 | D35: 정상 | E35: P2 | F35: SIM-02 완료 상태 | G35: 1. 세 경로 카드를 차례로 선택 / 2. 배 경로 표에서 나라별로 어느 배가 방문했는지 모은다 | H35: 모든 경로에서 각 나라는 한 척의 배에만 나타난다 (같은 나라가 두 배에 나뉘지 않음) | I35: FR-4 | J35: #details 의 배 경로 표 | K35: N | L35: 미확인 | N35: 미작성 | O35: PRD FR-4. 표 구조를 파싱해야 해서 구현 난이도 중간
A36: CNF-01 | B36: 주문 확정 | C36: 메모 없이 주문 확정 | D36: 정상 | E36: P1 | F36: SIM-02 완료 상태 | G36: 1. '주문 확정' 클릭 | H36: /orders/{id} 상세로 이동. 상태 '확정', 작성자 admin, 메모 '-'. 상태 이력 1건(이전 '-' → 새 '확정') | I36: FR-8, FR-14, FR-21 | J36: #confirmBtn → /orders/\d+ | K36: Y | L36: 있음(OrderFlowTests, 서비스 수준) | N36: 미작성
A37: CNF-02 | B37: 주문 확정 | C37: 메모 입력 후 확정 | D37: 정상 | E37: P2 | F37: SIM-02 완료 상태 | G37: 1. #memo 에 '테스트 메모' 입력 2. '주문 확정' 클릭 | H37: 상세의 메모 항목에 '테스트 메모' 가 표시된다 | I37: FR-8 | J37: #memo | K37: Y | L37: 없음 | N37: 미작성
A38: CNF-03 | B38: 주문 확정 | C38: 선택한 경로로 확정 | D38: 정상 | E38: P1 | F38: SIM-02 완료 상태 | G38: 1. '가장 빠르게' 카드 선택 2. '주문 확정' 클릭 | H38: 상세의 경로가 '가장 빠르게', 소요 일수·비용이 선택 카드와 같다 | I38: FR-8, FR-11 | J38: #options .option[data-type=FAST] | K38: Y | L38: 미확인 | N38: 미작성
A39: CNF-04 | B39: 주문 확정 | C39: 시뮬레이션 전에는 확정 영역이 보이지 않음 | D39: 정상 | E39: P2 | F39: SIM-01 상태 | G39: 1. 결과 영역 확인 | H39: #result 가 hidden 이라 '주문 확정' 을 누를 수 없다 | I39: INTENT 의도 3 | J39: #result[hidden] | K39: N | L39: 미확인 | N39: 미작성
A40: CNF-05 | B40: 주문 확정 | C40: 메모 최대 길이(1000자) 제한 | D40: 경계 | E40: P3 | F40: SIM-02 완료 상태 | G40: 1. #memo 에 1001자 입력 | H40: textarea maxlength 로 1000자까지만 입력된다 | I40: FR-8 | J40: #memo[maxlength=1000] | K40: N | L40: 미확인 | N40: 미작성
A41: CNF-06 | B41: 주문 확정 | C41: 시뮬레이션 후 마스터 변경 시 확정 거부(409) | D41: 예외 | E41: P1 | F41: 마스터 원복 방법 준비(afterEach) | G41: 1. 컨텍스트 A: 시뮬레이션 실행 2. 컨텍스트 B: 마스터에서 배 척수 변경 후 저장 3. 컨텍스트 A: '주문 확정' 클릭 | H41: #confirmError 에 '시뮬레이션 이후 마스터 데이터가 바뀌었습니다. 다시 시뮬레이션해 주세요' 표시. 주문이 생성되지 않는다. 다시 시뮬레이션하면 확정된다 | I41: FR-10 | J41: #confirmError, 두 번째 browser context | K41: Y | L41: 있음(OrderFlowTests, 서비스 수준) | N41: 미작성 | O41: 마스터 버전은 올라가면 되돌릴 수 없음(값만 원복)
A42: CNF-07 | B42: 주문 확정 | C42: 확정한 주문이 목록 맨 위에 나타남 | D42: 정상 | E42: P2 | F42: 확정 전 목록의 전체 건수 N 기록 | G42: 1. 주문 확정 2. /orders 이동 | H42: 첫 행이 방금 만든 주문(#id)이고 '전체' 건수가 N+1, '확정' 건수가 1 증가한다 | I42: FR-12 | J42: .chip .count, tbody tr:first-child | K42: Y | L42: 미확인 | N42: 미작성 | O42: 절대값이 아니라 전후 차이로 검증
...

Sheet 요약
A1: 시나리오 요약
A2: 모든 수치는 '시나리오' 시트에서 수식으로 집계됩니다.
A4: 영역 | B4: P1 | C4: P2 | D4: P3 | E4: 합계 | F4: 구현 완료 | G4: 구현율 | H4: 담당자 미배정
A5: 인증 | B5: =COUNTIFS(시나리오!$B$5:$B$78,$A5,시나리오!$E$5:$E$78,"P1") -> 4 | C5: =COUNTIFS(시나리오!$B$5:$B$78,$A5,시나리오!$E$5:$E$78,"P2") -> 2 | D5: =COUNTIFS(시나리오!$B$5:$B$78,$A5,시나리오!$E$5:$E$78,"P3") -> 3 | E5: =SUM(B5:D5) -> 9 | F5: =COUNTIFS(시나리오!$B$5:$B$78,$A5,시나리오!$N$5:$N$78,"완료") -> 0 | G5: =IF(E5=0,0,F5/E5) -> 0 | H5: =COUNTIFS(시나리오!$B$5:$B$78,$A5,시나리오!$M$5:$M$78,"") -> 9
A6: 주문 추가·시뮬레이션 | B6: =COUNTIFS(시나리오!$B$5:$B$78,$A6,시나리오!$E$5:$E$78,"P1") -> 6 | C6: =COUNTIFS(시나리오!$B$5:$B$78,$A6,시나리오!$E$5:$E$78,"P2") -> 13 | D6: =COUNTIFS(시나리오!$B$5:$B$78,$A6,시나리오!$E$5:$E$78,"P3") -> 3 | E6: =SUM(B6:D6) -> 22 | F6: =COUNTIFS(시나리오!$B$5:$B$78,$A6,시나리오!$N$5:$N$78,"완료") -> 0 | G6: =IF(E6=0,0,F6/E6) -> 0 | H6: =COUNTIFS(시나리오!$B$5:$B$78,$A6,시나리오!$M$5:$M$78,"") -> 22
A7: 주문 확정 | B7: =COUNTIFS(시나리오!$B$5:$B$78,$A7,시나리오!$E$5:$E$78,"P1") -> 3 | C7: =COUNTIFS(시나리오!$B$5:$B$78,$A7,시나리오!$E$5:$E$78,"P2") -> 4 | D7: =COUNTIFS(시나리오!$B$5:$B$78,$A7,시나리오!$E$5:$E$78,"P3") -> 1 | E7: =SUM(B7:D7) -> 8 | F7: =COUNTIFS(시나리오!$B$5:$B$78,$A7,시나리오!$N$5:$N$78,"완료") -> 0 | G7: =IF(E7=0,0,F7/E7) -> 0 | H7: =COUNTIFS(시나리오!$B$5:$B$78,$A7,시나리오!$M$5:$M$78,"") -> 8
A8: 주문 목록 | B8: =COUNTIFS(시나리오!$B$5:$B$78,$A8,시나리오!$E$5:$E$78,"P1") -> 2 | C8: =COUNTIFS(시나리오!$B$5:$B$78,$A8,시나리오!$E$5:$E$78,"P2") -> 2 | D8: =COUNTIFS(시나리오!$B$5:$B$78,$A8,시나리오!$E$5:$E$78,"P3") -> 2 | E8: =SUM(B8:D8) -> 6 | F8: =COUNTIFS(시나리오!$B$5:$B$78,$A8,시나리오!$N$5:$N$78,"완료") -> 0 | G8: =IF(E8=0,0,F8/E8) -> 0 | H8: =COUNTIFS(시나리오!$B$5:$B$78,$A8,시나리오!$M$5:$M$78,"") -> 6
A9: 주문 상세·상태 | B9: =COUNTIFS(시나리오!$B$5:$B$78,$A9,시나리오!$E$5:$E$78,"P1") -> 6 | C9: =COUNTIFS(시나리오!$B$5:$B$78,$A9,시나리오!$E$5:$E$78,"P2") -> 4 | D9: =COUNTIFS(시나리오!$B$5:$B$78,$A9,시나리오!$E$5:$E$78,"P3") -> 0 | E9: =SUM(B9:D9) -> 10 | F9: =COUNTIFS(시나리오!$B$5:$B$78,$A9,시나리오!$N$5:$N$78,"완료") -> 0 | G9: =IF(E9=0,0,F9/E9) -> 0 | H9: =COUNTIFS(시나리오!$B$5:$B$78,$A9,시나리오!$M$5:$M$78,"") -> 10
A10: 마스터 데이터 | B10: =COUNTIFS(시나리오!$B$5:$B$78,$A10,시나리오!$E$5:$E$78,"P1") -> 5 | C10: =COUNTIFS(시나리오!$B$5:$B$78,$A10,시나리오!$E$5:$E$78,"P2") -> 5 | D10: =COUNTIFS(시나리오!$B$5:$B$78,$A10,시나리오!$E$5:$E$78,"P3") -> 0 | E10: =SUM(B10:D10) -> 10 | F10: =COUNTIFS(시나리오!$B$5:$B$78,$A10,시나리오!$N$5:$N$78,"완료") -> 0 | G10: =IF(E10=0,0,F10/E10) -> 0 | H10: =COUNTIFS(시나리오!$B$5:$B$78,$A10,시나리오!$M$5:$M$78,"") -> 10
A11: API | B11: =COUNTIFS(시나리오!$B$5:$B$78,$A11,시나리오!$E$5:$E$78,"P1") -> 1 | C11: =COUNTIFS(시나리오!$B$5:$B$78,$A11,시나리오!$E$5:$E$78,"P2") -> 4 | D11: =COUNTIFS(시나리오!$B$5:$B$78,$A11,시나리오!$E$5:$E$78,"P3") -> 2 | E11: =SUM(B11:D11) -> 7 | F11: =COUNTIFS(시나리오!$B$5:$B$78,$A11,시나리오!$N$5:$N$78,"완료") -> 0 | G11: =IF(E11=0,0,F11/E11) -> 0 | H11: =COUNTIFS(시나리오!$B$5:$B$78,$A11,시나리오!$M$5:$M$78,"") -> 7
A12: 종합 흐름 | B12: =COUNTIFS(시나리오!$B$5:$B$78,$A12,시나리오!$E$5:$E$78,"P1") -> 1 | C12: =COUNTIFS(시나리오!$B$5:$B$78,$A12,시나리오!$E$5:$E$78,"P2") -> 1 | D12: =COUNTIFS(시나리오!$B$5:$B$78,$A12,시나리오!$E$5:$E$78,"P3") -> 0 | E12: =SUM(B12:D12) -> 2 | F12: =COUNTIFS(시나리오!$B$5:$B$78,$A12,시나리오!$N$5:$N$78,"완료") -> 0 | G12: =IF(E12=0,0,F12/E12) -> 0 | H12: =COUNTIFS(시나리오!$B$5:$B$78,$A12,시나리오!$M$5:$M$78,"") -> 2
A13: 합계 | B13: =SUM(B5:B12) -> 28 | C13: =SUM(C5:C12) -> 35 | D13: =SUM(D5:D12) -> 11 | E13: =SUM(E5:E12) -> 74 | F13: =SUM(F5:F12) -> 0 | G13: =IF(E13=0,0,F13/E13) -> 0 | H13: =SUM(H5:H12) -> 74
A15: 유형별 / DB 변경
A16: 구분 | B16: 건수
A17: 정상 | B17: =COUNTIF(시나리오!$D$5:$D$78,A17) -> 41
A18: 예외 | B18: =COUNTIF(시나리오!$D$5:$D$78,A18) -> 21
A19: 경계 | B19: =COUNTIF(시나리오!$D$5:$D$78,A19) -> 12
A20: DB 변경 있음(Y) | B20: =COUNTIF(시나리오!$K$5:$K$78,"Y") -> 21
A21: DB 변경 없음(N) | B21: =COUNTIF(시나리오!$K$5:$K$78,"N") -> 53
A23: ※ 'DB 변경 있음' 시나리오는 실행할 때마다 서버의 실제 데이터(주문, 마스터 버전)가 바뀝니다. '확인 필요 사항' #5 참고.
A25: 통합 현황
A26: 항목 | B26: 건수
A27: 초안 A 시나리오 | B27: 65
A28: 초안 B 시나리오 | B28: 34
A29: 초안 C 시나리오(흐름형) | B29: 10
A30: 통합 시나리오 수 | B30: =COUNTA(시나리오!$A$5:$A$78) -> 74
A31: 그중 신규로 추가한 시나리오 | B31: =B30-COUNTIF(시나리오!#REF!,"*초안 A*") -> #REF!
A33: 초안 건수(파란색)는 각 초안 파일에서 센 값입니다.

Sheet 테스트 데이터
A1: 테스트 데이터
A2: 출처: 앱 시작 시 들어가는 기본 마스터 값(BatteryService.initDefaults) · 노란색 칸은 직접 바꿔 볼 수 있는 입력값 · 파란 글자는 하드코딩 입력값, 검정은 수식
A4: 1. 공장 기본값과 기본 주문(12,000K 균등 분배)의 예상 결과
A5: 나라 | B5: 하루 최대 생산(K) | C5: 재고 상한(K) | D5: 셀당 원가(원) | E5: 주문 수량(K) | F5: 예상 방문 횟수 | G5: 예상 생산비(억원)
A6: 중국 | B6: 400 | C6: 4000 | D6: 700 | E6: 3000 | F6: =IF(E6>0,ROUNDUP(E6/C6,0),0) -> 1 | G6: =E6*1000*D6/100000000 -> 21
A7: 일본 | B7: 800 | C7: 2000 | D7: 900 | E7: 3000 | F7: =IF(E7>0,ROUNDUP(E7/C7,0),0) -> 2 | G7: =E7*1000*D7/100000000 -> 27
A8: 베트남 | B8: 200 | C8: 10000 | D8: 550 | E8: 3000 | F8: =IF(E8>0,ROUNDUP(E8/C8,0),0) -> 1 | G8: =E8*1000*D8/100000000 -> 16.5
A9: 인도네시아 | B9: 300 | C9: 7000 | D9: 450 | E9: 3000 | F9: =IF(E9>0,ROUNDUP(E9/C9,0),0) -> 1 | G9: =E9*1000*D9/100000000 -> 13.5
A10: 합계 | E10: =SUM(E6:E9) -> 12000 | F10: =SUM(F6:F9) -> 5 | G10: =SUM(G6:G9) -> 78
A11: 방문 횟수 = 올림(주문 수량 ÷ 재고 상한), 생산비 = 주문(K) × 1,000 × 셀당 원가 ÷ 1억. SIM-01 기대값(중국 1·일본 2·베트남 1·인도네시아 1), SIM-20 기대값(78.00억원)과 같다.
A13: 2. 항로 기본값(항해 일수, 양방향)
A14: 출발 | B14: 도착 | C14: 일수
A15: 한국 | B15: 중국 | C15: 1
A16: 한국 | B16: 일본 | C16: 2
A17: 한국 | B17: 베트남 | C17: 5
A18: 한국 | B18: 인도네시아 | C18: 7
A19: 중국 | B19: 일본 | C19: 2
A20: 중국 | B20: 베트남 | C20: 4
A21: 중국 | B21: 인도네시아 | C21: 6
A22: 일본 | B22: 베트남 | C22: 5
A23: 일본 | B23: 인도네시아 | C23: 7
A24: 베트남 | B24: 인도네시아 | C24: 2
A25: 기타: 배 3척, 척당 일 운항비 1억 원(= 100,000,000원), 마스터 버전 1(초기).
A27: 3. 경계값 입력표
A28: 항목 | B28: 허용 최소 | C28: 허용 최대 | D28: 거부 예시(아래) | E28: 거부 예시(위) | F28: 관련 시나리오
A29: 총 생산 필요 수(K) | B29: 1 | C29: 100000 | D29: 0 | E29: 100001 | F29: SIM-10 ~ 13
A30: 배 척수 | B30: 1 | C30: 4 | D30: 0 | E30: 5 | F30: MST-05
A31: 항해 일수 | B31: 1 | C31: 365 | D31: 0 | E31: 366 | F31: MST-06
A32: 하루 최대 생산량(K) | B32: 1 | C32: 1000000 | D32: 0 | E32: 1000001 | F32: MST-03
A33: 재고 상한(K) | B33: 1 | C33: 1000000 | D33: 0 | E33: 1000001 | F33: MST-03
A34: 셀당 원가(원) | B34: 1 | C34: 100000000 | D34: 0 | E34: 100000001 | F34: MST-03
A35: 메모 길이(자) | B35: 0 | C35: 1000 | D35: - | E35: 1001 | F35: CNF-05, API-06
A36: 출처: 마스터 저장·주문 검증 코드의 상수. 값이 바뀌면 이 표와 관련 시나리오를 함께 고친다.
A38: 4. 계정
A39: 아이디 | B39: 비밀번호 | C39: 비고
A40: admin | B40: admin | C40: 유일한 계정(하드코딩). 사용자 구분 없음

Sheet 확인 필요 사항
A1: 테스트 설계 중 발견한 확인 사항
A2: 초안 A의 항목을 이어받고, 통합 과정에서 나온 항목을 추가했다. '검증 수준' 열에서 직접 확인한 것과 추정을 구분했다.
A4: # | B4: 구분 | C4: 내용 | D4: 근거 / 검증 수준 | E4: 영향 시나리오 | F4: 제안
A5: 1 | B5: 결함 의심 | C5: 존재하지 않는 주문 번호로 상세 조회하면 HTTP 500 이 응답된다. | D5: 실행 서버에서 GET /orders/999999 → 500 확인함. BatteryService.getOrder 가 BusinessException 을 던지는데 컨트롤러가 화면 요청에서는 처리하지 않음. | E5: DTL-08 | F5: 404 또는 목록으로 안내하도록 처리. 수정 전까지는 '현재 500' 을 알려진 이슈로 표시.
A6: 2 | B6: 결함 의심 | C6: 주문을 취소하면 주문 행을 삭제한 뒤 /orders/{id} 로 리다이렉트하므로 오류 화면이 나올 수 있다. | D6: 코드 추정(changeStatus 의 orders.delete 후 redirect:/orders/{id}). 아직 실행해 보지 않음 → DTL-05 로 확인. | E6: DTL-05, DTL-06 | F6: 취소 후에는 목록으로 이동하고 메시지를 보여주는 흐름이 자연스러움.
A7: 3 | B7: 의도 확인 | C7: '취소' 상태 주문은 삭제되므로 목록의 '취소' 칩 건수는 항상 0 이 된다. | D7: 코드 추정. 이력 테이블에는 남지만 화면에서 조회할 방법이 없다. | E7: LST-01, DTL-06 | F7: 취소 주문을 보관/조회해야 하는지 고객 확인(PRD.md 열린 질문 Q2).
A8: 4 | B8: 테스트 기법 | C8: 마스터 입력칸의 min/max 속성 때문에 브라우저 검증이 먼저 막아 서버 검증 메시지를 볼 수 없다. | D8: master.html 의 input min/max. 코드 확인. | E8: MST-03~07 | F8: 테스트에서 form.noValidate = true 로 브라우저 검증을 끄고 서버 오류 경로를 검증.
A9: 5 | B9: 데이터 오염 | C9: 테스트가 실행 중인 서버(파일 DB ./data/battery)를 그대로 사용하므로 주문과 마스터 버전이 계속 쌓인다. | D9: playwright.config.ts 가 기존 서버를 사용하도록 설정됨. 마스터 버전은 한 번 올라가면 되돌릴 수 없다. | E9: 'DB 변경: Y' 전체 | F9: 각 테스트가 afterEach 에서 마스터 값을 원복하고, 건수는 절대값이 아닌 전후 차이로 검증. 가능하면 테스트 전용 인메모리 서버를 별도 포트로 사용.
A10: 6 | B10: 테스트 기법 | C10: 취소·상태 변경 시 확인 대화상자(confirm)가 뜬다. | D10: order-detail.html 의 submit 핸들러. 코드 확인. | E10: DTL-02~05 | F10: page.on('dialog', d => d.accept()) 를 클릭 전에 등록.
A11: 7 | B11: 테스트 기법 | C11: 동시 변경·마스터 충돌 시나리오는 서로 다른 browser context(세션) 두 개가 필요하다. | D11: 충돌 판정은 서버의 version 비교. 코드 확인. | E11: CNF-06, DTL-07 | F11: browser.newContext() 로 두 사용자를 만들고 로그인.
A12: 8 | B12: 성능 | C12: 100,000K 처럼 방문 횟수가 많은 입력은 Planner 의 완전 탐색 계산이 오래 걸릴 수 있다. | D12: 추정. Planner 가 분할 × 왕복 패턴 × 순열을 모두 탐색함. 실제 시간은 SIM-12 로 측정 필요. | E12: SIM-12 | F12: 응답 시간 기준(예: 10초)을 정하고 test.setTimeout 을 늘림.
A13: 9 | B13: 테스트 기법 | C13: 지도 애니메이션은 자동 재생이라 스냅샷 비교가 불안정하다. | D13: anim.js 의 requestAnimationFrame 기반 진행. | E13: SIM-16 | F13: 요소 존재와 값 변화만 확인하고 시각 비교는 하지 않음.
A14: 10 | B14: 범위 | C14: 단일 계정이라 권한별 시나리오(담당자/관리자)는 작성하지 않았다. | D14: PRD.md 의 범위 밖 항목. | E14: - | F14: 권한 구분이 생기면 AUTH 영역에 추가.
A15: 11 | B15: 탐색 필요 | C15: 두 사람이 동시에 기준 정보를 저장하면 한쪽이 오류가 날 수 있고, 그때 사용자에게 어떻게 안내할지 정해져 있지 않다. | D15: 코드 확인(기준 정보 저장에도 동시 수정 방지가 있고, 이 오류를 처리하는 곳이 보이지 않음). 실행은 미확인. PRD 리스크 '기준 정보 동시 저장' 과 같은 내용. | E15: MST-10 | F15: 기대 동작(오류 안내 방식)을 팀이 먼저 정한 뒤 시나리오를 확정.
A16: 12 | B16: 현재 동작 | C16: 총 수량에 0 을 입력하면 이전 숫자로 되돌아가기만 하고 안내 문구는 나오지 않는다. | D16: 초안 C(소스에서 읽은 동작). 실행은 미확인. | E16: SIM-10 | F16: 안내가 필요한지 팀이 정하고, 필요하면 기대 결과를 고친다.
A17: 13 | B17: 범위 | C17: 우선순위 표기가 초안마다 달랐다(P1/P2/P3 vs 상/중/하). 통합본은 P1/P2/P3 로 통일했고, 같은 시나리오의 우선순위 차이는 '출처 매핑' 시트에 적었다. | D17: 통합 과정에서 확인. | E17: - | F17: 차이가 난 항목은 팀 리뷰에서 최종 확정.

Sheet 출처 매핑
A1: 출처 매핑 (중복 제거 내역)
A2: 초안 B·C 의 각 시나리오가 통합본의 어느 시나리오로 합쳐졌는지 보여 준다. 초안 A 65개는 ID 를 그대로 유지했다.
A4: 출처 파일 | B4: 출처 ID | C4: 출처 시나리오 | D4: 처리 | E4: 통합 ID | F4: 비고
A5: 초안 B | B5: AUTH-01 | C5: 로그인 성공 | D5: 중복 통합 | E5: AUTH-02
A6: 초안 B | B6: AUTH-02 | C6: 잘못된 비밀번호로 로그인 실패 | D6: 중복 통합 | E6: AUTH-03
A7: 초안 B | B7: AUTH-03 | C7: 비로그인 상태에서 보호된 화면 접근 차단 | D7: 중복 통합 | E7: AUTH-01
A8: 초안 B | B8: AUTH-04 | C8: 로그아웃 | D8: 중복 통합 | E8: AUTH-05 | F8: 우선순위: 초안 B '중'(P2) → 통합본 P1
A9: 초안 B | B9: AUTH-05 | C9: 로그인 상태에서 /login 접근 | D9: 중복 통합 | E9: AUTH-04
A10: 초안 B | B10: AUTH-06 | C10: 비로그인 상태에서 API 호출 시 401 | D10: 중복 통합 | E10: AUTH-07 | F10: 우선순위: 초안 B '하'(P3) → 통합본 P2
A11: 초안 B | B11: NEW-01 | C11: 초기 화면 기본값 | D11: 중복 통합 | E11: SIM-01
A12: 초안 B | B12: NEW-02 | C12: 게이지 조정 시 오른쪽 나라가 반대로 조정 | D12: 중복 통합 | E12: SIM-06 | F12: 맨 오른쪽 조정은 SIM-07 에서 다룸
A13: 초안 B | B13: NEW-03 | C13: 게이지 값은 인접 나라와의 합을 넘지 못함 | D13: 중복 통합 | E13: SIM-08
A14: 초안 B | B14: NEW-04 | C14: 총 생산 필요 수 변경 시 균등 분배 | D14: 중복 통합 | E14: SIM-05 | F14: 우선순위: 초안 B '중'(P2) → 통합본 P1
A15: 초안 B | B15: NEW-05 | C15: 총 생산 필요 수에 0 입력 시 이전 값 복귀 | D15: 중복 통합 | E15: SIM-10
A16: 초안 B | B16: NEW-06 | C16: 입력이 바뀌면 이전 시뮬레이션 결과가 사라짐 | D16: 중복 통합 | E16: SIM-09
A17: 초안 B | B17: SIM-01 | C17: 시뮬레이션 실행 시 경로 3개 표시 | D17: 중복 통합 | E17: SIM-02
A18: 초안 B | B18: SIM-02 | C18: 경로 선택 전환 | D18: 중복 통합 | E18: SIM-03
A19: 초안 B | B19: SIM-03 | C19: 총량 상한(100,000K) 초과 시 오류 | D19: 중복 통합 | E19: SIM-13 | F19: 우선순위: 초안 B '중'(P2) → 통합본 P1
A20: 초안 B | B20: SIM-04 | C20: 지도 애니메이션 영역 표시 | D20: 중복 통합 | E20: SIM-16
A21: 초안 B | B21: CONF-01 | C21: 주문 확정 후 상세 화면으로 이동 | D21: 중복 통합 | E21: CNF-01
A22: 초안 B | B22: CONF-02 | C22: 메모와 함께 확정 | D22: 중복 통합 | E22: CNF-02
A23: 초안 B | B23: CONF-03 | C23: 시뮬레이션 후 마스터가 바뀌면 확정 거부 | D23: 중복 통합 | E23: CNF-06
A24: 초안 B | B24: LIST-01 | C24: 목록 표시와 상태별 건수 | D24: 중복 통합 | E24: LST-01
A25: 초안 B | B25: LIST-02 | C25: 상태 필터 | D25: 중복 통합 | E25: LST-02 | F25: 우선순위: 초안 B '중'(P2) → 통합본 P1
A26: 초안 B | B26: LIST-03 | C26: 주문이 없을 때 안내 문구 | D26: 중복 통합 | E26: LST-04
A27: 초안 B | B27: LIST-04 | C27: 행 클릭으로 상세 이동 | D27: 중복 통합 | E27: LST-03
A28: 초안 B | B28: STAT-01 | C28: 확정 → 진행 | D28: 중복 통합 | E28: DTL-02
A29: 초안 B | B29: STAT-02 | C29: 진행 → 완료 후 최종 상태 | D29: 중복 통합 | E29: DTL-03
A30: 초안 B | B30: STAT-03 | C30: 확인창에서 취소하면 상태 불변 | D30: 중복 통합 | E30: DTL-04
A31: 초안 B | B31: STAT-04 | C31: 확정 상태에서는 완료로 바로 갈 수 없음 | D31: 신규 반영 | E31: DTL-10
A32: 초안 B | B32: STAT-05 | C32: 동시 변경 충돌 | D32: 중복 통합 | E32: DTL-07
A33: 초안 B | B33: STAT-06 | C33: [탐색] 확정/진행 주문 취소 | D33: 중복 통합 | E33: DTL-05
A34: 초안 B | B34: MAST-01 | C34: 현재 값 표시 | D34: 중복 통합 | E34: MST-01 | F34: 우선순위: 초안 B '중'(P2) → 통합본 P1
A35: 초안 B | B35: MAST-02 | C35: 값 수정 후 저장 성공 | D35: 중복 통합 | E35: MST-02
A36: 초안 B | B36: MAST-03 | C36: 잘못된 값은 저장되지 않고 이유 표시 | D36: 중복 통합 | E36: MST-03
A37: 초안 B | B37: MAST-04 | C37: 마스터 수정 후에도 기존 주문 상세는 그대로 | D37: 중복 통합 | E37: MST-09
A38: 초안 B | B38: NAV-01 | C38: 상단 메뉴 이동 | D38: 중복 통합 | E38: LST-05
A39: 초안 C | B39: #1 | C39: 로그인과 접근 제한 | D39: 중복 통합 | E39: AUTH-01, AUTH-02, AUTH-03, AUTH-06 | F39: 흐름형 시나리오를 원자 시나리오로 나눠 흡수
A40: 초안 C | B40: #2 | C40: 수량 조절과 기본 시뮬레이션 | D40: 중복 통합 | E40: SIM-02, SIM-03, SIM-04, SIM-06, SIM-15 | F40: 흐름형 시나리오를 원자 시나리오로 나눠 흡수
A41: 초안 C | B41: #3 | C41: 입력 경계값 검증 | D41: 중복 통합 | E41: SIM-10, SIM-12, SIM-13 | F41: 흐름형 시나리오를 원자 시나리오로 나눠 흡수
...
